{"uuid": "07a289af-ba78-4df3-8c68-fe8b975271f0", "counter": 36, "stdout": "\u001b[0;31mAn exception occurred during task execution. To see the full traceback, use -vvv. The error was: NameError: global name 'soa_rdataset' is not defined\u001b[0m\r\n\u001b[0;31mfatal: [dnszone_dnszone_1]: FAILED! => {\"changed\": false, \"module_stderr\": \"Traceback (most recent call last):\\n  File \\\"/root/.ansible/tmp/ansible-tmp-1565576622.6482174-201073414487313/AnsiballZ_dnszone.py\\\", line 114, in <module>\\n    _ansiballz_main()\\n  File \\\"/root/.ansible/tmp/ansible-tmp-1565576622.6482174-201073414487313/AnsiballZ_dnszone.py\\\", line 106, in _ansiballz_main\\n    invoke_module(zipped_mod, temp_path, ANSIBALLZ_PARAMS)\\n  File \\\"/root/.ansible/tmp/ansible-tmp-1565576622.6482174-201073414487313/AnsiballZ_dnszone.py\\\", line 49, in invoke_module\\n    imp.load_module('__main__', mod, module, MOD_DESC)\\n  File \\\"/tmp/ansible_dnszone_payload_Tnr02Q/__main__.py\\\", line 118, in <module>\\n  File \\\"/tmp/ansible_dnszone_payload_Tnr02Q/__main__.py\\\", line 115, in main\\n  File \\\"/tmp/ansible_dnszone_payload_Tnr02Q/__main__.py\\\", line 81, in ensure\\n  File \\\"/tmp/ansible_dnszone_payload_Tnr02Q/__main__.py\\\", line 62, in build_zone\\nNameError: global name 'soa_rdataset' is not defined\\n\", \"module_stdout\": \"\", \"msg\": \"MODULE FAILURE\\nSee stdout/stderr for the exact error\", \"rc\": 1}\u001b[0m", "start_line": 34, "end_line": 36, "runner_ident": "28603559-d93a-4f74-9f02-18fd4fd20b49", "event": "runner_on_failed", "event_data": {"playbook": "integrations.yml", "playbook_uuid": "bbdd16e7-7559-47ae-9015-13672b8fbf86", "play": "Run tests(s)", "play_uuid": "1c1b0dec-55e8-b423-a651-000000000009", "play_pattern": "containers", "task": "TEST1 | create zone", "task_uuid": "1c1b0dec-55e8-b423-a651-00000000003a", "task_action": "dnszone", "task_args": "", "task_path": "/home/phil/git/ansible-modules/tests/integrations/dnszone/tasks.yml:10", "host": "dnszone_dnszone_1", "remote_addr": "dnszone_dnszone_1", "res": {"module_stdout": "", "module_stderr": "Traceback (most recent call last):\n  File \"/root/.ansible/tmp/ansible-tmp-1565576622.6482174-201073414487313/AnsiballZ_dnszone.py\", line 114, in <module>\n    _ansiballz_main()\n  File \"/root/.ansible/tmp/ansible-tmp-1565576622.6482174-201073414487313/AnsiballZ_dnszone.py\", line 106, in _ansiballz_main\n    invoke_module(zipped_mod, temp_path, ANSIBALLZ_PARAMS)\n  File \"/root/.ansible/tmp/ansible-tmp-1565576622.6482174-201073414487313/AnsiballZ_dnszone.py\", line 49, in invoke_module\n    imp.load_module('__main__', mod, module, MOD_DESC)\n  File \"/tmp/ansible_dnszone_payload_Tnr02Q/__main__.py\", line 118, in <module>\n  File \"/tmp/ansible_dnszone_payload_Tnr02Q/__main__.py\", line 115, in main\n  File \"/tmp/ansible_dnszone_payload_Tnr02Q/__main__.py\", line 81, in ensure\n  File \"/tmp/ansible_dnszone_payload_Tnr02Q/__main__.py\", line 62, in build_zone\nNameError: global name 'soa_rdataset' is not defined\n", "exception": "Traceback (most recent call last):\n  File \"/root/.ansible/tmp/ansible-tmp-1565576622.6482174-201073414487313/AnsiballZ_dnszone.py\", line 114, in <module>\n    _ansiballz_main()\n  File \"/root/.ansible/tmp/ansible-tmp-1565576622.6482174-201073414487313/AnsiballZ_dnszone.py\", line 106, in _ansiballz_main\n    invoke_module(zipped_mod, temp_path, ANSIBALLZ_PARAMS)\n  File \"/root/.ansible/tmp/ansible-tmp-1565576622.6482174-201073414487313/AnsiballZ_dnszone.py\", line 49, in invoke_module\n    imp.load_module('__main__', mod, module, MOD_DESC)\n  File \"/tmp/ansible_dnszone_payload_Tnr02Q/__main__.py\", line 118, in <module>\n  File \"/tmp/ansible_dnszone_payload_Tnr02Q/__main__.py\", line 115, in main\n  File \"/tmp/ansible_dnszone_payload_Tnr02Q/__main__.py\", line 81, in ensure\n  File \"/tmp/ansible_dnszone_payload_Tnr02Q/__main__.py\", line 62, in build_zone\nNameError: global name 'soa_rdataset' is not defined\n", "msg": "MODULE FAILURE\nSee stdout/stderr for the exact error", "rc": 1, "_ansible_no_log": false, "changed": false}, "ignore_errors": null, "event_loop": null, "pid": 27280}, "pid": 27280, "created": "2019-08-12T02:23:44.092554", "parent_uuid": "1c1b0dec-55e8-b423-a651-00000000003a"}